<?xml version="1.0" ?>
<!-- =================================================================================== -->
<!-- |    This document was autogenerated by xacro from fl_robot01.xacro               | -->
<!-- |    EDITING THIS FILE BY HAND IS NOT RECOMMENDED                                 | -->
<!-- =================================================================================== -->
<robot name="robot_description">
  

#
  <param command="./urdf/fl_robot01.xacro" name="robot_description"/>
  <static>true</static>
  <!--Gazebo Color Properties-->
  <gazebo reference="base_link">
    <material>Gazebo/Blue</material>
  </gazebo>
  <gazebo reference="top_cover">
    <!--    <material>Gazebo/GreenTransparentOverlay</material> -->
    <material>Gazebo/Green</material>
  </gazebo>
  <gazebo reference="left_wheel">
    <material>Gazebo/Yellow</material>
  </gazebo>
  <gazebo reference="right_wheel">
    <material>Gazebo/Green</material>
  </gazebo>
  <gazebo reference="sensor_laser">
    <material>Gazebo/Gray</material>
  </gazebo>
  <gazebo reference="north">
    <material>Gazebo/Blue</material>
  </gazebo>
  <gazebo reference="caster_wheel">
    <material>Gazebo/Blue</material>
    <mu1>0.0</mu1>
    <mu2>0.0</mu2>
    <slip1>1.0</slip1>
    <slip2>1.0</slip2>
    <selfCollide>true</selfCollide>
    <gravity>true</gravity>
  </gazebo>
  <material name="blue">
    <color rgba="0 0 0.8 1"/>
  </material>
  <material name="black">
    <color rgba="0 0 0 1"/>
  </material>
  <material name="white">
    <color rgba="1 1 1 1"/>
  </material>
  <material name="red">
    <color rgba="0.8 0.0 0.0 1.0"/>
  </material>
  <material name="mycolor">
    <color rgba="0.1 0.2 0.2 1.0"/>
  </material>
  <!--Base Footprint-->
  <link name="base_footprint">
    <inertial>
      <mass value="10"/>
      <inertia ixx="1.6666666666666667e-06" ixy="0.0" ixz="0.0" iyy="1.6666666666666667e-06" iyz="0.0" izz="1.6666666666666667e-06"/>
    </inertial>
    <visual>
      <origin rpy="0 0 0" xyz="0 0 0"/>
      <geometry>
        <box size="0.001 0.001 0.001"/>
      </geometry>
    </visual>
  </link>
  <!--Base link-->
  <link name="base_link">
    <inertial>
      <mass value="1"/>
      <inertia ixx="0.0021416666666666667" ixy="0.0" ixz="0.0" iyy="0.004266666666666667" iyz="0.0" izz="0.0021416666666666667"/>
    </inertial>
    <visual>
      <geometry>
        <box size="0.16 0.16 0.07"/>
      </geometry>
      <!--      <material name="black"/> -->
    </visual>
    <collision>
      <geometry>
        <box size="0.16 0.16 0.07"/>
      </geometry>
    </collision>
  </link>
  <link name="top_cover">
    <inertial>
      <mass value="1"/>
      <inertia ixx="0.005633333333333333" ixy="0" ixz="0" iyy="0.005633333333333333" iyz="0" izz="0.01125"/>
    </inertial>
    <visual>
      <origin rpy="0 0 0" xyz="0 0 0"/>
      <geometry>
        <cylinder length="0.01" radius="0.15"/>
      </geometry>
      <!--      <material name="mycolor" /> -->
    </visual>
    <collision name="cover_collision">
      <origin rpy="0 0 0" xyz="0 0 0"/>
      <geometry>
        <cylinder length="0.01" radius="0.15"/>
      </geometry>
    </collision>
    <sensor name="my_contact" type="contact">
      <contact>
        <collision>cover_collision</collision>
      </contact>
    </sensor>
  </link>
  <link name="north">
    <visual>
      <origin rpy="0 0 0" xyz="0 0 0"/>
      <geometry>
        <cylinder length="0.001" radius="0.01"/>
      </geometry>
    </visual>
    <collision name="north_collision">
      <origin rpy="0 0 0" xyz="0 0 0"/>
      <geometry>
        <cylinder length="0.001" radius="0.01"/>
      </geometry>
    </collision>
  </link>
  <joint name="north_cover_joint" type="fixed">
    <axis rpy="0 0 0" xyz="0 1 0"/>
    <parent link="top_cover"/>
    <child link="north"/>
    <origin rpy="0 0 0" xyz=" 0.13999999999999999 0 0.005"/>
  </joint>
  <joint name="cover_base_joint" type="fixed">
    <axis rpy="0 0 0" xyz="0 1 0"/>
    <parent link="base_link"/>
    <child link="top_cover"/>
    <origin rpy="0 0 0" xyz=" 0 0 0.04"/>
  </joint>
  <!--base_link to base_footprint Joint-->
  <joint name="base_link_joint" type="fixed">
    <origin rpy="0 0 0" xyz="0 0 0.04"/>
    <parent link="base_footprint"/>
    <child link="base_link"/>
  </joint>
  <link name="left_wheel">
    <visual>
      <origin rpy="1.5707963267948966 0 0" xyz="0 0 0"/>
      <geometry>
        <cylinder length="0.005" radius="0.035"/>
      </geometry>
      <material name="white"/>
    </visual>
    <collision>
      <origin rpy="1.5707963267948966 0 0" xyz="0 0 0"/>
      <geometry>
        <cylinder length="0.005" radius="0.035"/>
      </geometry>
      <surface>
        <friction>
          <ode>
            <mu>200.0</mu>
            <mu2>100.0</mu2>
          </ode>
        </friction>
      </surface>
    </collision>
    <inertial>
      <mass value="1"/>
      <inertia ixx="0.00030833333333333337" ixy="0" ixz="0" iyy="0.00030833333333333337" iyz="0" izz="0.0006125000000000001"/>
    </inertial>
  </link>
  <joint name="left_wheel_joint" type="continuous">
    <axis rpy="0 0 0" xyz="0 1 0"/>
    <parent link="base_link"/>
    <child link="left_wheel"/>
    <origin rpy="0 0 0" xyz="-0.02 0.08700000000000001 -0.005"/>
  </joint>
  <transmission name="left_wheel_transmission">
    <type>transmission_interface/SimpleTransmission</type>
    <actuator name="${prefix}_motor">
      <mechanicalReduction>0</mechanicalReduction>
    </actuator>
    <joint name="left_wheel_joint">
      <hardwareInterface>hardware_interface/VelocityJointInterface</hardwareInterface>
    </joint>
  </transmission>
  <link name="right_wheel">
    <visual>
      <origin rpy="-1.5707963267948966 0 0" xyz="0 0 0"/>
      <geometry>
        <cylinder length="0.005" radius="0.035"/>
      </geometry>
      <material name="white"/>
    </visual>
    <collision>
      <origin rpy="-1.5707963267948966 0 0" xyz="0 0 0"/>
      <geometry>
        <cylinder length="0.005" radius="0.035"/>
      </geometry>
      <surface>
        <friction>
          <ode>
            <mu>200.0</mu>
            <mu2>100.0</mu2>
          </ode>
        </friction>
      </surface>
    </collision>
    <inertial>
      <mass value="1"/>
      <inertia ixx="0.00030833333333333337" ixy="0" ixz="0" iyy="0.00030833333333333337" iyz="0" izz="0.0006125000000000001"/>
    </inertial>
  </link>
  <joint name="right_wheel_joint" type="continuous">
    <axis rpy="0 0 0" xyz="0 1 0"/>
    <parent link="base_link"/>
    <child link="right_wheel"/>
    <origin rpy="0 0 0" xyz="-0.02 -0.08700000000000001 -0.005"/>
  </joint>
  <transmission name="right_wheel_transmission">
    <type>transmission_interface/SimpleTransmission</type>
    <actuator name="${prefix}_motor">
      <mechanicalReduction>0</mechanicalReduction>
    </actuator>
    <joint name="right_wheel_joint">
      <hardwareInterface>hardware_interface/VelocityJointInterface</hardwareInterface>
    </joint>
  </transmission>
  <!--Caster Wheel Link-->
  <link name="caster_wheel">
    <visual>
      <origin rpy="0 0 0" xyz="0 0 0"/>
      <geometry>
        <sphere radius="0.0175"/>
      </geometry>
      <material name="blue"/>
    </visual>
    <collision>
      <origin rpy="0 0 0" xyz="0 0 0"/>
      <geometry>
        <sphere radius="0.0175"/>
      </geometry>
    </collision>
    <inertial>
      <mass value="1"/>
      <inertia ixx="0.00012250000000000002" ixy="0.0" ixz="0.0" iyy="0.00012250000000000002" iyz="0.0" izz="0.00012250000000000002"/>
    </inertial>
  </link>
  <!--Caster Wheel Joint-->
  <joint name="caster_wheel_joint" type="continuous">
    <axis rpy="0 0 0" xyz="0 1 0"/>
    <parent link="base_link"/>
    <child link="caster_wheel"/>
    <origin rpy="0 0 0" xyz="0.052 0 -0.022500000000000003"/>
  </joint>
  <link name="sensor_laser">
    <visual>
      <geometry>
        <cylinder length="0.04" radius="0.015"/>
      </geometry>
      <material name="blue"/>
    </visual>
    <collision>
      <geometry>
        <cylinder length="0.04" radius="0.015"/>
      </geometry>
    </collision>
    <inertial>
      <mass value="0.2"/>
      <inertia ixx="4.1666666666666665e-05" ixy="0.0" ixz="0.0" iyy="2.9999999999999997e-05" iyz="0.0" izz="4.1666666666666665e-05"/>
    </inertial>
  </link>
  <joint name="sensor_laser_joint" type="fixed">
    <origin rpy="0 0 0" xyz="0 0 0.025"/>
    <parent link="top_cover"/>
    <child link="sensor_laser"/>
  </joint>
  <gazebo>
    <plugin filename="libgazebo_ros_diff_drive.so" name="differential_drive_controller">
      <alwaysOn>false</alwaysOn>
      <legacyMode>false</legacyMode>
      <updateRate>20</updateRate>
      <leftJoint>left_wheel_joint</leftJoint>
      <rightJoint>right_wheel_joint</rightJoint>
      <wheelSeparation>0.174</wheelSeparation>
      <wheelDiameter>0.07</wheelDiameter>
      <torque>20</torque>
      <commandTopic>/mv_fl_robot/base_controller/cmd_vel</commandTopic>
      <odometryTopic>/mv_fl_robot/base_controller/odom</odometryTopic>
      <odometryFrame>odom</odometryFrame>
      <robotBaseFrame>base_footprint</robotBaseFrame>
    </plugin>
  </gazebo>
  <!--Gazebo Hokuyo Laser Plugin-->
  <gazebo reference="sensor_laser">
    <sensor name="head_hokuyo_sensor" type="ray">
      <pose>0 0 0 0 0 0</pose>
      <visualize>false</visualize>
      <update_rate>20</update_rate>
      <ray>
        <scan>
          <horizontal>
            <samples>1440</samples>
            <resolution>1</resolution>
            <min_angle>-3.14159</min_angle>
            <max_angle>3.14159</max_angle>
          </horizontal>
        </scan>
        <range>
          <min>0.10</min>
          <max>30.0</max>
          <resolution>0.01</resolution>
        </range>
        <noise>
          <type>gaussian</type>
          <mean>0.0</mean>
          <stddev>0.01</stddev>
        </noise>
      </ray>
      <plugin filename="libgazebo_ros_laser.so" name="gazebo_ros_head_hokuyo_controller">
        <topicName>/mv_fl_robot/laser_scan/scan</topicName>
        <frameName>sensor_laser</frameName>
      </plugin>
    </sensor>
  </gazebo>
  <!-- Add ROS plugin so we can interact with our robot -->
  <gazebo>
    <plugin filename="libgazebo_ros_control.so" name="gazebo_ros_control">
      <robotNamespace>/</robotNamespace>
    </plugin>
  </gazebo>
</robot>
